2019-06-15 14:03:03,511 - INFO - Informational message
2019-06-17 11:35:37,550 - INFO - Received signal 2 (SIGINT), stopping...
2019-06-17 11:35:39,072 - WARNING - Exiting immediately!
2019-06-17 11:52:58,073 - INFO - Received signal 2 (SIGINT), stopping...
2019-06-17 11:52:58,360 - WARNING - Exiting immediately!
2019-06-17 11:53:22,475 - ERROR - An uncaught error was raised while processing the update
Traceback (most recent call last):
  File "/home/sherhin/projects/elate_bot/env/lib/python3.6/site-packages/telegram/ext/dispatcher.py", line 279, in process_update
    handler.handle_update(update, self)
  File "/home/sherhin/projects/elate_bot/env/lib/python3.6/site-packages/telegram/ext/conversationhandler.py", line 305, in handle_update
    new_state = self.current_handler.handle_update(update, dispatcher)
  File "/home/sherhin/projects/elate_bot/env/lib/python3.6/site-packages/telegram/ext/messagehandler.py", line 169, in handle_update
    return self.callback(dispatcher.bot, update, **optional_args)
  File "bot.py", line 40, in profile_get_name
    profile_get_age()
TypeError: profile_get_age() missing 3 required positional arguments: 'bot', 'update', and 'user_data'
2019-06-17 11:54:19,648 - WARNING - Retrying (Retry(total=2, connect=None, read=None, redirect=None)) after connection broken by 'ConnectTimeoutError(<telegram.vendor.ptb_urllib3.urllib3.contrib.socks.SOCKSHTTPSConnection object at 0x7fd5491cbef0>, 'Connection to api.telegram.org timed out. (connect timeout=5.0)')': /bot804749789:AAGJPNOlbummUTJzQHPdhcNqy7JbVAT-f2Q/getUpdates
2019-06-17 11:55:01,105 - INFO - Received signal 2 (SIGINT), stopping...
2019-06-17 11:55:01,285 - WARNING - Exiting immediately!
2019-06-17 11:56:55,440 - INFO - Received signal 2 (SIGINT), stopping...
2019-06-17 11:56:55,620 - WARNING - Exiting immediately!
2019-06-17 11:57:38,264 - ERROR - An uncaught error was raised while processing the update
Traceback (most recent call last):
  File "/home/sherhin/projects/elate_bot/env/lib/python3.6/site-packages/telegram/ext/dispatcher.py", line 279, in process_update
    handler.handle_update(update, self)
  File "/home/sherhin/projects/elate_bot/env/lib/python3.6/site-packages/telegram/ext/conversationhandler.py", line 305, in handle_update
    new_state = self.current_handler.handle_update(update, dispatcher)
  File "/home/sherhin/projects/elate_bot/env/lib/python3.6/site-packages/telegram/ext/messagehandler.py", line 169, in handle_update
    return self.callback(dispatcher.bot, update, **optional_args)
  File "bot.py", line 40, in profile_get_name
    text = f'Оке,{profile_name}, сколько тебе лет?'
NameError: name 'profile_name' is not defined
2019-06-17 11:57:42,470 - ERROR - An uncaught error was raised while processing the update
Traceback (most recent call last):
  File "/home/sherhin/projects/elate_bot/env/lib/python3.6/site-packages/telegram/ext/dispatcher.py", line 279, in process_update
    handler.handle_update(update, self)
  File "/home/sherhin/projects/elate_bot/env/lib/python3.6/site-packages/telegram/ext/conversationhandler.py", line 305, in handle_update
    new_state = self.current_handler.handle_update(update, dispatcher)
  File "/home/sherhin/projects/elate_bot/env/lib/python3.6/site-packages/telegram/ext/messagehandler.py", line 169, in handle_update
    return self.callback(dispatcher.bot, update, **optional_args)
  File "bot.py", line 40, in profile_get_name
    text = f'Оке,{profile_name}, сколько тебе лет?'
NameError: name 'profile_name' is not defined
2019-06-17 11:57:45,048 - ERROR - An uncaught error was raised while processing the update
Traceback (most recent call last):
  File "/home/sherhin/projects/elate_bot/env/lib/python3.6/site-packages/telegram/ext/dispatcher.py", line 279, in process_update
    handler.handle_update(update, self)
  File "/home/sherhin/projects/elate_bot/env/lib/python3.6/site-packages/telegram/ext/conversationhandler.py", line 305, in handle_update
    new_state = self.current_handler.handle_update(update, dispatcher)
  File "/home/sherhin/projects/elate_bot/env/lib/python3.6/site-packages/telegram/ext/messagehandler.py", line 169, in handle_update
    return self.callback(dispatcher.bot, update, **optional_args)
  File "bot.py", line 40, in profile_get_name
    text = f'Оке,{profile_name}, сколько тебе лет?'
NameError: name 'profile_name' is not defined
2019-06-17 11:57:47,558 - ERROR - An uncaught error was raised while processing the update
Traceback (most recent call last):
  File "/home/sherhin/projects/elate_bot/env/lib/python3.6/site-packages/telegram/ext/dispatcher.py", line 279, in process_update
    handler.handle_update(update, self)
  File "/home/sherhin/projects/elate_bot/env/lib/python3.6/site-packages/telegram/ext/conversationhandler.py", line 305, in handle_update
    new_state = self.current_handler.handle_update(update, dispatcher)
  File "/home/sherhin/projects/elate_bot/env/lib/python3.6/site-packages/telegram/ext/messagehandler.py", line 169, in handle_update
    return self.callback(dispatcher.bot, update, **optional_args)
  File "bot.py", line 40, in profile_get_name
    text = f'Оке,{profile_name}, сколько тебе лет?'
NameError: name 'profile_name' is not defined
2019-06-17 11:58:28,464 - INFO - Received signal 2 (SIGINT), stopping...
2019-06-17 11:58:28,644 - WARNING - Exiting immediately!
2019-06-17 12:01:42,443 - ERROR - An uncaught error was raised while processing the update
Traceback (most recent call last):
  File "/home/sherhin/projects/elate_bot/env/lib/python3.6/site-packages/telegram/ext/dispatcher.py", line 279, in process_update
    handler.handle_update(update, self)
  File "/home/sherhin/projects/elate_bot/env/lib/python3.6/site-packages/telegram/ext/conversationhandler.py", line 305, in handle_update
    new_state = self.current_handler.handle_update(update, dispatcher)
  File "/home/sherhin/projects/elate_bot/env/lib/python3.6/site-packages/telegram/ext/messagehandler.py", line 169, in handle_update
    return self.callback(dispatcher.bot, update, **optional_args)
TypeError: profile_get_age() missing 1 required positional argument: 'profile_name'
2019-06-17 12:08:45,307 - INFO - Received signal 2 (SIGINT), stopping...
2019-06-17 12:08:45,523 - WARNING - Exiting immediately!
2019-06-17 12:25:31,033 - INFO - Received signal 2 (SIGINT), stopping...
2019-06-17 12:25:31,212 - WARNING - Exiting immediately!
2019-06-17 15:59:44,257 - INFO - Received signal 2 (SIGINT), stopping...
2019-06-17 15:59:45,289 - WARNING - Exiting immediately!
2019-06-17 16:16:12,917 - WARNING - Retrying (Retry(total=2, connect=None, read=None, redirect=None)) after connection broken by 'NewConnectionError('<telegram.vendor.ptb_urllib3.urllib3.contrib.socks.SOCKSHTTPSConnection object at 0x7f88dc10c2b0>: Failed to establish a new connection: [Errno -2] Name or service not known',)': /bot804749789:AAGJPNOlbummUTJzQHPdhcNqy7JbVAT-f2Q/getUpdates
2019-06-17 16:16:13,022 - WARNING - Retrying (Retry(total=1, connect=None, read=None, redirect=None)) after connection broken by 'NewConnectionError('<telegram.vendor.ptb_urllib3.urllib3.contrib.socks.SOCKSHTTPSConnection object at 0x7f88dc10c438>: Failed to establish a new connection: [Errno -2] Name or service not known',)': /bot804749789:AAGJPNOlbummUTJzQHPdhcNqy7JbVAT-f2Q/getUpdates
2019-06-17 16:16:13,025 - WARNING - Retrying (Retry(total=0, connect=None, read=None, redirect=None)) after connection broken by 'NewConnectionError('<telegram.vendor.ptb_urllib3.urllib3.contrib.socks.SOCKSHTTPSConnection object at 0x7f88dc10ccc0>: Failed to establish a new connection: [Errno -2] Name or service not known',)': /bot804749789:AAGJPNOlbummUTJzQHPdhcNqy7JbVAT-f2Q/getUpdates
2019-06-17 16:16:13,054 - ERROR - Error while getting Updates: urllib3 HTTPError SOCKSHTTPSConnectionPool(host='api.telegram.org', port=443): Max retries exceeded with url: /bot804749789:AAGJPNOlbummUTJzQHPdhcNqy7JbVAT-f2Q/getUpdates (Caused by NewConnectionError('<telegram.vendor.ptb_urllib3.urllib3.contrib.socks.SOCKSHTTPSConnection object at 0x7f88dc10ce48>: Failed to establish a new connection: [Errno -2] Name or service not known',))
2019-06-17 16:16:13,055 - ERROR - No error handlers are registered, logging exception.
Traceback (most recent call last):
  File "/home/sherhin/projects/elate_bot/env/lib/python3.6/site-packages/telegram/vendor/ptb_urllib3/urllib3/contrib/socks.py", line 88, in _new_conn
    **extra_kw
  File "/home/sherhin/projects/elate_bot/env/lib/python3.6/site-packages/socks.py", line 180, in create_connection
    for r in socket.getaddrinfo(proxy_addr, proxy_port, 0, socket.SOCK_STREAM):
  File "/usr/lib/python3.6/socket.py", line 745, in getaddrinfo
    for res in _socket.getaddrinfo(host, port, family, type, proto, flags):
socket.gaierror: [Errno -2] Name or service not known

During handling of the above exception, another exception occurred:

Traceback (most recent call last):
  File "/home/sherhin/projects/elate_bot/env/lib/python3.6/site-packages/telegram/vendor/ptb_urllib3/urllib3/connectionpool.py", line 617, in urlopen
    chunked=chunked)
  File "/home/sherhin/projects/elate_bot/env/lib/python3.6/site-packages/telegram/vendor/ptb_urllib3/urllib3/connectionpool.py", line 360, in _make_request
    self._validate_conn(conn)
  File "/home/sherhin/projects/elate_bot/env/lib/python3.6/site-packages/telegram/vendor/ptb_urllib3/urllib3/connectionpool.py", line 857, in _validate_conn
    super(HTTPSConnectionPool, self)._validate_conn(conn)
  File "/home/sherhin/projects/elate_bot/env/lib/python3.6/site-packages/telegram/vendor/ptb_urllib3/urllib3/connectionpool.py", line 289, in _validate_conn
    conn.connect()
  File "/home/sherhin/projects/elate_bot/env/lib/python3.6/site-packages/telegram/vendor/ptb_urllib3/urllib3/connection.py", line 284, in connect
    conn = self._new_conn()
  File "/home/sherhin/projects/elate_bot/env/lib/python3.6/site-packages/telegram/vendor/ptb_urllib3/urllib3/contrib/socks.py", line 120, in _new_conn
    self, "Failed to establish a new connection: %s" % e)
telegram.vendor.ptb_urllib3.urllib3.exceptions.NewConnectionError: <telegram.vendor.ptb_urllib3.urllib3.contrib.socks.SOCKSHTTPSConnection object at 0x7f88dc10ce48>: Failed to establish a new connection: [Errno -2] Name or service not known

During handling of the above exception, another exception occurred:

Traceback (most recent call last):
  File "/home/sherhin/projects/elate_bot/env/lib/python3.6/site-packages/telegram/utils/request.py", line 203, in _request_wrapper
    resp = self._con_pool.request(*args, **kwargs)
  File "/home/sherhin/projects/elate_bot/env/lib/python3.6/site-packages/telegram/vendor/ptb_urllib3/urllib3/request.py", line 70, in request
    **urlopen_kw)
  File "/home/sherhin/projects/elate_bot/env/lib/python3.6/site-packages/telegram/vendor/ptb_urllib3/urllib3/request.py", line 148, in request_encode_body
    return self.urlopen(method, url, **extra_kw)
  File "/home/sherhin/projects/elate_bot/env/lib/python3.6/site-packages/telegram/vendor/ptb_urllib3/urllib3/poolmanager.py", line 244, in urlopen
    response = conn.urlopen(method, u.request_uri, **kw)
  File "/home/sherhin/projects/elate_bot/env/lib/python3.6/site-packages/telegram/vendor/ptb_urllib3/urllib3/connectionpool.py", line 695, in urlopen
    **response_kw)
  File "/home/sherhin/projects/elate_bot/env/lib/python3.6/site-packages/telegram/vendor/ptb_urllib3/urllib3/connectionpool.py", line 695, in urlopen
    **response_kw)
  File "/home/sherhin/projects/elate_bot/env/lib/python3.6/site-packages/telegram/vendor/ptb_urllib3/urllib3/connectionpool.py", line 695, in urlopen
    **response_kw)
  File "/home/sherhin/projects/elate_bot/env/lib/python3.6/site-packages/telegram/vendor/ptb_urllib3/urllib3/connectionpool.py", line 666, in urlopen
    _stacktrace=sys.exc_info()[2])
  File "/home/sherhin/projects/elate_bot/env/lib/python3.6/site-packages/telegram/vendor/ptb_urllib3/urllib3/util/retry.py", line 376, in increment
    raise MaxRetryError(_pool, url, error or ResponseError(cause))
telegram.vendor.ptb_urllib3.urllib3.exceptions.MaxRetryError: SOCKSHTTPSConnectionPool(host='api.telegram.org', port=443): Max retries exceeded with url: /bot804749789:AAGJPNOlbummUTJzQHPdhcNqy7JbVAT-f2Q/getUpdates (Caused by NewConnectionError('<telegram.vendor.ptb_urllib3.urllib3.contrib.socks.SOCKSHTTPSConnection object at 0x7f88dc10ce48>: Failed to establish a new connection: [Errno -2] Name or service not known',))

During handling of the above exception, another exception occurred:

Traceback (most recent call last):
  File "/home/sherhin/projects/elate_bot/env/lib/python3.6/site-packages/telegram/ext/updater.py", line 319, in _network_loop_retry
    if not action_cb():
  File "/home/sherhin/projects/elate_bot/env/lib/python3.6/site-packages/telegram/ext/updater.py", line 280, in polling_action_cb
    allowed_updates=allowed_updates)
  File "/home/sherhin/projects/elate_bot/env/lib/python3.6/site-packages/telegram/bot.py", line 65, in decorator
    result = func(self, *args, **kwargs)
  File "/home/sherhin/projects/elate_bot/env/lib/python3.6/site-packages/telegram/bot.py", line 1975, in get_updates
    result = self._request.post(url, data, timeout=float(read_latency) + float(timeout))
  File "/home/sherhin/projects/elate_bot/env/lib/python3.6/site-packages/telegram/utils/request.py", line 309, in post
    headers={'Content-Type': 'application/json'})
  File "/home/sherhin/projects/elate_bot/env/lib/python3.6/site-packages/telegram/utils/request.py", line 209, in _request_wrapper
    raise NetworkError('urllib3 HTTPError {0}'.format(error))
telegram.error.NetworkError: urllib3 HTTPError SOCKSHTTPSConnectionPool(host='api.telegram.org', port=443): Max retries exceeded with url: /bot804749789:AAGJPNOlbummUTJzQHPdhcNqy7JbVAT-f2Q/getUpdates (Caused by NewConnectionError('<telegram.vendor.ptb_urllib3.urllib3.contrib.socks.SOCKSHTTPSConnection object at 0x7f88dc10ce48>: Failed to establish a new connection: [Errno -2] Name or service not known',))
2019-06-17 16:16:14,058 - WARNING - Retrying (Retry(total=2, connect=None, read=None, redirect=None)) after connection broken by 'NewConnectionError('<telegram.vendor.ptb_urllib3.urllib3.contrib.socks.SOCKSHTTPSConnection object at 0x7f88dc10cc18>: Failed to establish a new connection: [Errno -2] Name or service not known',)': /bot804749789:AAGJPNOlbummUTJzQHPdhcNqy7JbVAT-f2Q/getUpdates
2019-06-17 16:16:15,686 - WARNING - Retrying (Retry(total=1, connect=None, read=None, redirect=None)) after connection broken by 'NewConnectionError('<telegram.vendor.ptb_urllib3.urllib3.contrib.socks.SOCKSHTTPSConnection object at 0x7f88df947390>: Failed to establish a new connection: [Errno -2] Name or service not known',)': /bot804749789:AAGJPNOlbummUTJzQHPdhcNqy7JbVAT-f2Q/getUpdates
2019-06-17 16:16:15,688 - WARNING - Retrying (Retry(total=0, connect=None, read=None, redirect=None)) after connection broken by 'NewConnectionError('<telegram.vendor.ptb_urllib3.urllib3.contrib.socks.SOCKSHTTPSConnection object at 0x7f88dc10cb70>: Failed to establish a new connection: [Errno -2] Name or service not known',)': /bot804749789:AAGJPNOlbummUTJzQHPdhcNqy7JbVAT-f2Q/getUpdates
2019-06-17 16:16:15,690 - ERROR - Error while getting Updates: urllib3 HTTPError SOCKSHTTPSConnectionPool(host='api.telegram.org', port=443): Max retries exceeded with url: /bot804749789:AAGJPNOlbummUTJzQHPdhcNqy7JbVAT-f2Q/getUpdates (Caused by NewConnectionError('<telegram.vendor.ptb_urllib3.urllib3.contrib.socks.SOCKSHTTPSConnection object at 0x7f88dc10ca20>: Failed to establish a new connection: [Errno -2] Name or service not known',))
2019-06-17 16:16:15,690 - ERROR - No error handlers are registered, logging exception.
Traceback (most recent call last):
  File "/home/sherhin/projects/elate_bot/env/lib/python3.6/site-packages/telegram/vendor/ptb_urllib3/urllib3/contrib/socks.py", line 88, in _new_conn
    **extra_kw
  File "/home/sherhin/projects/elate_bot/env/lib/python3.6/site-packages/socks.py", line 180, in create_connection
    for r in socket.getaddrinfo(proxy_addr, proxy_port, 0, socket.SOCK_STREAM):
  File "/usr/lib/python3.6/socket.py", line 745, in getaddrinfo
    for res in _socket.getaddrinfo(host, port, family, type, proto, flags):
socket.gaierror: [Errno -2] Name or service not known

During handling of the above exception, another exception occurred:

Traceback (most recent call last):
  File "/home/sherhin/projects/elate_bot/env/lib/python3.6/site-packages/telegram/vendor/ptb_urllib3/urllib3/connectionpool.py", line 617, in urlopen
    chunked=chunked)
  File "/home/sherhin/projects/elate_bot/env/lib/python3.6/site-packages/telegram/vendor/ptb_urllib3/urllib3/connectionpool.py", line 360, in _make_request
    self._validate_conn(conn)
  File "/home/sherhin/projects/elate_bot/env/lib/python3.6/site-packages/telegram/vendor/ptb_urllib3/urllib3/connectionpool.py", line 857, in _validate_conn
    super(HTTPSConnectionPool, self)._validate_conn(conn)
  File "/home/sherhin/projects/elate_bot/env/lib/python3.6/site-packages/telegram/vendor/ptb_urllib3/urllib3/connectionpool.py", line 289, in _validate_conn
    conn.connect()
  File "/home/sherhin/projects/elate_bot/env/lib/python3.6/site-packages/telegram/vendor/ptb_urllib3/urllib3/connection.py", line 284, in connect
    conn = self._new_conn()
  File "/home/sherhin/projects/elate_bot/env/lib/python3.6/site-packages/telegram/vendor/ptb_urllib3/urllib3/contrib/socks.py", line 120, in _new_conn
    self, "Failed to establish a new connection: %s" % e)
telegram.vendor.ptb_urllib3.urllib3.exceptions.NewConnectionError: <telegram.vendor.ptb_urllib3.urllib3.contrib.socks.SOCKSHTTPSConnection object at 0x7f88dc10ca20>: Failed to establish a new connection: [Errno -2] Name or service not known

During handling of the above exception, another exception occurred:

Traceback (most recent call last):
  File "/home/sherhin/projects/elate_bot/env/lib/python3.6/site-packages/telegram/utils/request.py", line 203, in _request_wrapper
    resp = self._con_pool.request(*args, **kwargs)
  File "/home/sherhin/projects/elate_bot/env/lib/python3.6/site-packages/telegram/vendor/ptb_urllib3/urllib3/request.py", line 70, in request
    **urlopen_kw)
  File "/home/sherhin/projects/elate_bot/env/lib/python3.6/site-packages/telegram/vendor/ptb_urllib3/urllib3/request.py", line 148, in request_encode_body
    return self.urlopen(method, url, **extra_kw)
  File "/home/sherhin/projects/elate_bot/env/lib/python3.6/site-packages/telegram/vendor/ptb_urllib3/urllib3/poolmanager.py", line 244, in urlopen
    response = conn.urlopen(method, u.request_uri, **kw)
  File "/home/sherhin/projects/elate_bot/env/lib/python3.6/site-packages/telegram/vendor/ptb_urllib3/urllib3/connectionpool.py", line 695, in urlopen
    **response_kw)
  File "/home/sherhin/projects/elate_bot/env/lib/python3.6/site-packages/telegram/vendor/ptb_urllib3/urllib3/connectionpool.py", line 695, in urlopen
    **response_kw)
  File "/home/sherhin/projects/elate_bot/env/lib/python3.6/site-packages/telegram/vendor/ptb_urllib3/urllib3/connectionpool.py", line 695, in urlopen
    **response_kw)
  File "/home/sherhin/projects/elate_bot/env/lib/python3.6/site-packages/telegram/vendor/ptb_urllib3/urllib3/connectionpool.py", line 666, in urlopen
    _stacktrace=sys.exc_info()[2])
  File "/home/sherhin/projects/elate_bot/env/lib/python3.6/site-packages/telegram/vendor/ptb_urllib3/urllib3/util/retry.py", line 376, in increment
    raise MaxRetryError(_pool, url, error or ResponseError(cause))
telegram.vendor.ptb_urllib3.urllib3.exceptions.MaxRetryError: SOCKSHTTPSConnectionPool(host='api.telegram.org', port=443): Max retries exceeded with url: /bot804749789:AAGJPNOlbummUTJzQHPdhcNqy7JbVAT-f2Q/getUpdates (Caused by NewConnectionError('<telegram.vendor.ptb_urllib3.urllib3.contrib.socks.SOCKSHTTPSConnection object at 0x7f88dc10ca20>: Failed to establish a new connection: [Errno -2] Name or service not known',))

During handling of the above exception, another exception occurred:

Traceback (most recent call last):
  File "/home/sherhin/projects/elate_bot/env/lib/python3.6/site-packages/telegram/ext/updater.py", line 319, in _network_loop_retry
    if not action_cb():
  File "/home/sherhin/projects/elate_bot/env/lib/python3.6/site-packages/telegram/ext/updater.py", line 280, in polling_action_cb
    allowed_updates=allowed_updates)
  File "/home/sherhin/projects/elate_bot/env/lib/python3.6/site-packages/telegram/bot.py", line 65, in decorator
    result = func(self, *args, **kwargs)
  File "/home/sherhin/projects/elate_bot/env/lib/python3.6/site-packages/telegram/bot.py", line 1975, in get_updates
    result = self._request.post(url, data, timeout=float(read_latency) + float(timeout))
  File "/home/sherhin/projects/elate_bot/env/lib/python3.6/site-packages/telegram/utils/request.py", line 309, in post
    headers={'Content-Type': 'application/json'})
  File "/home/sherhin/projects/elate_bot/env/lib/python3.6/site-packages/telegram/utils/request.py", line 209, in _request_wrapper
    raise NetworkError('urllib3 HTTPError {0}'.format(error))
telegram.error.NetworkError: urllib3 HTTPError SOCKSHTTPSConnectionPool(host='api.telegram.org', port=443): Max retries exceeded with url: /bot804749789:AAGJPNOlbummUTJzQHPdhcNqy7JbVAT-f2Q/getUpdates (Caused by NewConnectionError('<telegram.vendor.ptb_urllib3.urllib3.contrib.socks.SOCKSHTTPSConnection object at 0x7f88dc10ca20>: Failed to establish a new connection: [Errno -2] Name or service not known',))
2019-06-17 16:16:17,197 - WARNING - Retrying (Retry(total=2, connect=None, read=None, redirect=None)) after connection broken by 'NewConnectionError('<telegram.vendor.ptb_urllib3.urllib3.contrib.socks.SOCKSHTTPSConnection object at 0x7f88df947550>: Failed to establish a new connection: [Errno -2] Name or service not known',)': /bot804749789:AAGJPNOlbummUTJzQHPdhcNqy7JbVAT-f2Q/getUpdates
2019-06-17 16:16:17,199 - WARNING - Retrying (Retry(total=1, connect=None, read=None, redirect=None)) after connection broken by 'NewConnectionError('<telegram.vendor.ptb_urllib3.urllib3.contrib.socks.SOCKSHTTPSConnection object at 0x7f88dc102dd8>: Failed to establish a new connection: [Errno -2] Name or service not known',)': /bot804749789:AAGJPNOlbummUTJzQHPdhcNqy7JbVAT-f2Q/getUpdates
2019-06-17 16:16:17,201 - WARNING - Retrying (Retry(total=0, connect=None, read=None, redirect=None)) after connection broken by 'NewConnectionError('<telegram.vendor.ptb_urllib3.urllib3.contrib.socks.SOCKSHTTPSConnection object at 0x7f88dc102cc0>: Failed to establish a new connection: [Errno -2] Name or service not known',)': /bot804749789:AAGJPNOlbummUTJzQHPdhcNqy7JbVAT-f2Q/getUpdates
2019-06-17 16:16:17,204 - ERROR - Error while getting Updates: urllib3 HTTPError SOCKSHTTPSConnectionPool(host='api.telegram.org', port=443): Max retries exceeded with url: /bot804749789:AAGJPNOlbummUTJzQHPdhcNqy7JbVAT-f2Q/getUpdates (Caused by NewConnectionError('<telegram.vendor.ptb_urllib3.urllib3.contrib.socks.SOCKSHTTPSConnection object at 0x7f88dc102208>: Failed to establish a new connection: [Errno -2] Name or service not known',))
2019-06-17 16:16:17,205 - ERROR - No error handlers are registered, logging exception.
Traceback (most recent call last):
  File "/home/sherhin/projects/elate_bot/env/lib/python3.6/site-packages/telegram/vendor/ptb_urllib3/urllib3/contrib/socks.py", line 88, in _new_conn
    **extra_kw
  File "/home/sherhin/projects/elate_bot/env/lib/python3.6/site-packages/socks.py", line 180, in create_connection
    for r in socket.getaddrinfo(proxy_addr, proxy_port, 0, socket.SOCK_STREAM):
  File "/usr/lib/python3.6/socket.py", line 745, in getaddrinfo
    for res in _socket.getaddrinfo(host, port, family, type, proto, flags):
socket.gaierror: [Errno -2] Name or service not known

During handling of the above exception, another exception occurred:

Traceback (most recent call last):
  File "/home/sherhin/projects/elate_bot/env/lib/python3.6/site-packages/telegram/vendor/ptb_urllib3/urllib3/connectionpool.py", line 617, in urlopen
    chunked=chunked)
  File "/home/sherhin/projects/elate_bot/env/lib/python3.6/site-packages/telegram/vendor/ptb_urllib3/urllib3/connectionpool.py", line 360, in _make_request
    self._validate_conn(conn)
  File "/home/sherhin/projects/elate_bot/env/lib/python3.6/site-packages/telegram/vendor/ptb_urllib3/urllib3/connectionpool.py", line 857, in _validate_conn
    super(HTTPSConnectionPool, self)._validate_conn(conn)
  File "/home/sherhin/projects/elate_bot/env/lib/python3.6/site-packages/telegram/vendor/ptb_urllib3/urllib3/connectionpool.py", line 289, in _validate_conn
    conn.connect()
  File "/home/sherhin/projects/elate_bot/env/lib/python3.6/site-packages/telegram/vendor/ptb_urllib3/urllib3/connection.py", line 284, in connect
    conn = self._new_conn()
  File "/home/sherhin/projects/elate_bot/env/lib/python3.6/site-packages/telegram/vendor/ptb_urllib3/urllib3/contrib/socks.py", line 120, in _new_conn
    self, "Failed to establish a new connection: %s" % e)
telegram.vendor.ptb_urllib3.urllib3.exceptions.NewConnectionError: <telegram.vendor.ptb_urllib3.urllib3.contrib.socks.SOCKSHTTPSConnection object at 0x7f88dc102208>: Failed to establish a new connection: [Errno -2] Name or service not known

During handling of the above exception, another exception occurred:

Traceback (most recent call last):
  File "/home/sherhin/projects/elate_bot/env/lib/python3.6/site-packages/telegram/utils/request.py", line 203, in _request_wrapper
    resp = self._con_pool.request(*args, **kwargs)
  File "/home/sherhin/projects/elate_bot/env/lib/python3.6/site-packages/telegram/vendor/ptb_urllib3/urllib3/request.py", line 70, in request
    **urlopen_kw)
  File "/home/sherhin/projects/elate_bot/env/lib/python3.6/site-packages/telegram/vendor/ptb_urllib3/urllib3/request.py", line 148, in request_encode_body
    return self.urlopen(method, url, **extra_kw)
  File "/home/sherhin/projects/elate_bot/env/lib/python3.6/site-packages/telegram/vendor/ptb_urllib3/urllib3/poolmanager.py", line 244, in urlopen
    response = conn.urlopen(method, u.request_uri, **kw)
  File "/home/sherhin/projects/elate_bot/env/lib/python3.6/site-packages/telegram/vendor/ptb_urllib3/urllib3/connectionpool.py", line 695, in urlopen
    **response_kw)
  File "/home/sherhin/projects/elate_bot/env/lib/python3.6/site-packages/telegram/vendor/ptb_urllib3/urllib3/connectionpool.py", line 695, in urlopen
    **response_kw)
  File "/home/sherhin/projects/elate_bot/env/lib/python3.6/site-packages/telegram/vendor/ptb_urllib3/urllib3/connectionpool.py", line 695, in urlopen
    **response_kw)
  File "/home/sherhin/projects/elate_bot/env/lib/python3.6/site-packages/telegram/vendor/ptb_urllib3/urllib3/connectionpool.py", line 666, in urlopen
    _stacktrace=sys.exc_info()[2])
  File "/home/sherhin/projects/elate_bot/env/lib/python3.6/site-packages/telegram/vendor/ptb_urllib3/urllib3/util/retry.py", line 376, in increment
    raise MaxRetryError(_pool, url, error or ResponseError(cause))
telegram.vendor.ptb_urllib3.urllib3.exceptions.MaxRetryError: SOCKSHTTPSConnectionPool(host='api.telegram.org', port=443): Max retries exceeded with url: /bot804749789:AAGJPNOlbummUTJzQHPdhcNqy7JbVAT-f2Q/getUpdates (Caused by NewConnectionError('<telegram.vendor.ptb_urllib3.urllib3.contrib.socks.SOCKSHTTPSConnection object at 0x7f88dc102208>: Failed to establish a new connection: [Errno -2] Name or service not known',))

During handling of the above exception, another exception occurred:

Traceback (most recent call last):
  File "/home/sherhin/projects/elate_bot/env/lib/python3.6/site-packages/telegram/ext/updater.py", line 319, in _network_loop_retry
    if not action_cb():
  File "/home/sherhin/projects/elate_bot/env/lib/python3.6/site-packages/telegram/ext/updater.py", line 280, in polling_action_cb
    allowed_updates=allowed_updates)
  File "/home/sherhin/projects/elate_bot/env/lib/python3.6/site-packages/telegram/bot.py", line 65, in decorator
    result = func(self, *args, **kwargs)
  File "/home/sherhin/projects/elate_bot/env/lib/python3.6/site-packages/telegram/bot.py", line 1975, in get_updates
    result = self._request.post(url, data, timeout=float(read_latency) + float(timeout))
  File "/home/sherhin/projects/elate_bot/env/lib/python3.6/site-packages/telegram/utils/request.py", line 309, in post
    headers={'Content-Type': 'application/json'})
  File "/home/sherhin/projects/elate_bot/env/lib/python3.6/site-packages/telegram/utils/request.py", line 209, in _request_wrapper
    raise NetworkError('urllib3 HTTPError {0}'.format(error))
telegram.error.NetworkError: urllib3 HTTPError SOCKSHTTPSConnectionPool(host='api.telegram.org', port=443): Max retries exceeded with url: /bot804749789:AAGJPNOlbummUTJzQHPdhcNqy7JbVAT-f2Q/getUpdates (Caused by NewConnectionError('<telegram.vendor.ptb_urllib3.urllib3.contrib.socks.SOCKSHTTPSConnection object at 0x7f88dc102208>: Failed to establish a new connection: [Errno -2] Name or service not known',))
2019-06-17 16:16:19,461 - WARNING - Retrying (Retry(total=2, connect=None, read=None, redirect=None)) after connection broken by 'NewConnectionError('<telegram.vendor.ptb_urllib3.urllib3.contrib.socks.SOCKSHTTPSConnection object at 0x7f88dc102278>: Failed to establish a new connection: [Errno -2] Name or service not known',)': /bot804749789:AAGJPNOlbummUTJzQHPdhcNqy7JbVAT-f2Q/getUpdates
2019-06-17 16:16:19,464 - WARNING - Retrying (Retry(total=1, connect=None, read=None, redirect=None)) after connection broken by 'NewConnectionError('<telegram.vendor.ptb_urllib3.urllib3.contrib.socks.SOCKSHTTPSConnection object at 0x7f88dc1020f0>: Failed to establish a new connection: [Errno -2] Name or service not known',)': /bot804749789:AAGJPNOlbummUTJzQHPdhcNqy7JbVAT-f2Q/getUpdates
2019-06-17 16:16:19,466 - WARNING - Retrying (Retry(total=0, connect=None, read=None, redirect=None)) after connection broken by 'NewConnectionError('<telegram.vendor.ptb_urllib3.urllib3.contrib.socks.SOCKSHTTPSConnection object at 0x7f88dc102470>: Failed to establish a new connection: [Errno -2] Name or service not known',)': /bot804749789:AAGJPNOlbummUTJzQHPdhcNqy7JbVAT-f2Q/getUpdates
2019-06-17 16:16:19,469 - ERROR - Error while getting Updates: urllib3 HTTPError SOCKSHTTPSConnectionPool(host='api.telegram.org', port=443): Max retries exceeded with url: /bot804749789:AAGJPNOlbummUTJzQHPdhcNqy7JbVAT-f2Q/getUpdates (Caused by NewConnectionError('<telegram.vendor.ptb_urllib3.urllib3.contrib.socks.SOCKSHTTPSConnection object at 0x7f88dc102f98>: Failed to establish a new connection: [Errno -2] Name or service not known',))
2019-06-17 16:16:19,469 - ERROR - No error handlers are registered, logging exception.
Traceback (most recent call last):
  File "/home/sherhin/projects/elate_bot/env/lib/python3.6/site-packages/telegram/vendor/ptb_urllib3/urllib3/contrib/socks.py", line 88, in _new_conn
    **extra_kw
  File "/home/sherhin/projects/elate_bot/env/lib/python3.6/site-packages/socks.py", line 180, in create_connection
    for r in socket.getaddrinfo(proxy_addr, proxy_port, 0, socket.SOCK_STREAM):
  File "/usr/lib/python3.6/socket.py", line 745, in getaddrinfo
    for res in _socket.getaddrinfo(host, port, family, type, proto, flags):
socket.gaierror: [Errno -2] Name or service not known

During handling of the above exception, another exception occurred:

Traceback (most recent call last):
  File "/home/sherhin/projects/elate_bot/env/lib/python3.6/site-packages/telegram/vendor/ptb_urllib3/urllib3/connectionpool.py", line 617, in urlopen
    chunked=chunked)
  File "/home/sherhin/projects/elate_bot/env/lib/python3.6/site-packages/telegram/vendor/ptb_urllib3/urllib3/connectionpool.py", line 360, in _make_request
    self._validate_conn(conn)
  File "/home/sherhin/projects/elate_bot/env/lib/python3.6/site-packages/telegram/vendor/ptb_urllib3/urllib3/connectionpool.py", line 857, in _validate_conn
    super(HTTPSConnectionPool, self)._validate_conn(conn)
  File "/home/sherhin/projects/elate_bot/env/lib/python3.6/site-packages/telegram/vendor/ptb_urllib3/urllib3/connectionpool.py", line 289, in _validate_conn
    conn.connect()
  File "/home/sherhin/projects/elate_bot/env/lib/python3.6/site-packages/telegram/vendor/ptb_urllib3/urllib3/connection.py", line 284, in connect
    conn = self._new_conn()
  File "/home/sherhin/projects/elate_bot/env/lib/python3.6/site-packages/telegram/vendor/ptb_urllib3/urllib3/contrib/socks.py", line 120, in _new_conn
    self, "Failed to establish a new connection: %s" % e)
telegram.vendor.ptb_urllib3.urllib3.exceptions.NewConnectionError: <telegram.vendor.ptb_urllib3.urllib3.contrib.socks.SOCKSHTTPSConnection object at 0x7f88dc102f98>: Failed to establish a new connection: [Errno -2] Name or service not known

During handling of the above exception, another exception occurred:

Traceback (most recent call last):
  File "/home/sherhin/projects/elate_bot/env/lib/python3.6/site-packages/telegram/utils/request.py", line 203, in _request_wrapper
    resp = self._con_pool.request(*args, **kwargs)
  File "/home/sherhin/projects/elate_bot/env/lib/python3.6/site-packages/telegram/vendor/ptb_urllib3/urllib3/request.py", line 70, in request
    **urlopen_kw)
  File "/home/sherhin/projects/elate_bot/env/lib/python3.6/site-packages/telegram/vendor/ptb_urllib3/urllib3/request.py", line 148, in request_encode_body
    return self.urlopen(method, url, **extra_kw)
  File "/home/sherhin/projects/elate_bot/env/lib/python3.6/site-packages/telegram/vendor/ptb_urllib3/urllib3/poolmanager.py", line 244, in urlopen
    response = conn.urlopen(method, u.request_uri, **kw)
  File "/home/sherhin/projects/elate_bot/env/lib/python3.6/site-packages/telegram/vendor/ptb_urllib3/urllib3/connectionpool.py", line 695, in urlopen
    **response_kw)
  File "/home/sherhin/projects/elate_bot/env/lib/python3.6/site-packages/telegram/vendor/ptb_urllib3/urllib3/connectionpool.py", line 695, in urlopen
    **response_kw)
  File "/home/sherhin/projects/elate_bot/env/lib/python3.6/site-packages/telegram/vendor/ptb_urllib3/urllib3/connectionpool.py", line 695, in urlopen
    **response_kw)
  File "/home/sherhin/projects/elate_bot/env/lib/python3.6/site-packages/telegram/vendor/ptb_urllib3/urllib3/connectionpool.py", line 666, in urlopen
    _stacktrace=sys.exc_info()[2])
  File "/home/sherhin/projects/elate_bot/env/lib/python3.6/site-packages/telegram/vendor/ptb_urllib3/urllib3/util/retry.py", line 376, in increment
    raise MaxRetryError(_pool, url, error or ResponseError(cause))
telegram.vendor.ptb_urllib3.urllib3.exceptions.MaxRetryError: SOCKSHTTPSConnectionPool(host='api.telegram.org', port=443): Max retries exceeded with url: /bot804749789:AAGJPNOlbummUTJzQHPdhcNqy7JbVAT-f2Q/getUpdates (Caused by NewConnectionError('<telegram.vendor.ptb_urllib3.urllib3.contrib.socks.SOCKSHTTPSConnection object at 0x7f88dc102f98>: Failed to establish a new connection: [Errno -2] Name or service not known',))

During handling of the above exception, another exception occurred:

Traceback (most recent call last):
  File "/home/sherhin/projects/elate_bot/env/lib/python3.6/site-packages/telegram/ext/updater.py", line 319, in _network_loop_retry
    if not action_cb():
  File "/home/sherhin/projects/elate_bot/env/lib/python3.6/site-packages/telegram/ext/updater.py", line 280, in polling_action_cb
    allowed_updates=allowed_updates)
  File "/home/sherhin/projects/elate_bot/env/lib/python3.6/site-packages/telegram/bot.py", line 65, in decorator
    result = func(self, *args, **kwargs)
  File "/home/sherhin/projects/elate_bot/env/lib/python3.6/site-packages/telegram/bot.py", line 1975, in get_updates
    result = self._request.post(url, data, timeout=float(read_latency) + float(timeout))
  File "/home/sherhin/projects/elate_bot/env/lib/python3.6/site-packages/telegram/utils/request.py", line 309, in post
    headers={'Content-Type': 'application/json'})
  File "/home/sherhin/projects/elate_bot/env/lib/python3.6/site-packages/telegram/utils/request.py", line 209, in _request_wrapper
    raise NetworkError('urllib3 HTTPError {0}'.format(error))
telegram.error.NetworkError: urllib3 HTTPError SOCKSHTTPSConnectionPool(host='api.telegram.org', port=443): Max retries exceeded with url: /bot804749789:AAGJPNOlbummUTJzQHPdhcNqy7JbVAT-f2Q/getUpdates (Caused by NewConnectionError('<telegram.vendor.ptb_urllib3.urllib3.contrib.socks.SOCKSHTTPSConnection object at 0x7f88dc102f98>: Failed to establish a new connection: [Errno -2] Name or service not known',))
2019-06-17 16:16:22,851 - WARNING - Retrying (Retry(total=2, connect=None, read=None, redirect=None)) after connection broken by 'NewConnectionError('<telegram.vendor.ptb_urllib3.urllib3.contrib.socks.SOCKSHTTPSConnection object at 0x7f88dc102c50>: Failed to establish a new connection: [Errno -2] Name or service not known',)': /bot804749789:AAGJPNOlbummUTJzQHPdhcNqy7JbVAT-f2Q/getUpdates
2019-06-17 16:16:22,856 - WARNING - Retrying (Retry(total=1, connect=None, read=None, redirect=None)) after connection broken by 'NewConnectionError('<telegram.vendor.ptb_urllib3.urllib3.contrib.socks.SOCKSHTTPSConnection object at 0x7f88dc102780>: Failed to establish a new connection: [Errno -2] Name or service not known',)': /bot804749789:AAGJPNOlbummUTJzQHPdhcNqy7JbVAT-f2Q/getUpdates
2019-06-17 16:16:22,859 - WARNING - Retrying (Retry(total=0, connect=None, read=None, redirect=None)) after connection broken by 'NewConnectionError('<telegram.vendor.ptb_urllib3.urllib3.contrib.socks.SOCKSHTTPSConnection object at 0x7f88dc102630>: Failed to establish a new connection: [Errno -2] Name or service not known',)': /bot804749789:AAGJPNOlbummUTJzQHPdhcNqy7JbVAT-f2Q/getUpdates
2019-06-17 16:16:22,860 - ERROR - Error while getting Updates: urllib3 HTTPError SOCKSHTTPSConnectionPool(host='api.telegram.org', port=443): Max retries exceeded with url: /bot804749789:AAGJPNOlbummUTJzQHPdhcNqy7JbVAT-f2Q/getUpdates (Caused by NewConnectionError('<telegram.vendor.ptb_urllib3.urllib3.contrib.socks.SOCKSHTTPSConnection object at 0x7f88dc1029b0>: Failed to establish a new connection: [Errno -2] Name or service not known',))
2019-06-17 16:16:22,861 - ERROR - No error handlers are registered, logging exception.
Traceback (most recent call last):
  File "/home/sherhin/projects/elate_bot/env/lib/python3.6/site-packages/telegram/vendor/ptb_urllib3/urllib3/contrib/socks.py", line 88, in _new_conn
    **extra_kw
  File "/home/sherhin/projects/elate_bot/env/lib/python3.6/site-packages/socks.py", line 180, in create_connection
    for r in socket.getaddrinfo(proxy_addr, proxy_port, 0, socket.SOCK_STREAM):
  File "/usr/lib/python3.6/socket.py", line 745, in getaddrinfo
    for res in _socket.getaddrinfo(host, port, family, type, proto, flags):
socket.gaierror: [Errno -2] Name or service not known

During handling of the above exception, another exception occurred:

Traceback (most recent call last):
  File "/home/sherhin/projects/elate_bot/env/lib/python3.6/site-packages/telegram/vendor/ptb_urllib3/urllib3/connectionpool.py", line 617, in urlopen
    chunked=chunked)
  File "/home/sherhin/projects/elate_bot/env/lib/python3.6/site-packages/telegram/vendor/ptb_urllib3/urllib3/connectionpool.py", line 360, in _make_request
    self._validate_conn(conn)
  File "/home/sherhin/projects/elate_bot/env/lib/python3.6/site-packages/telegram/vendor/ptb_urllib3/urllib3/connectionpool.py", line 857, in _validate_conn
    super(HTTPSConnectionPool, self)._validate_conn(conn)
  File "/home/sherhin/projects/elate_bot/env/lib/python3.6/site-packages/telegram/vendor/ptb_urllib3/urllib3/connectionpool.py", line 289, in _validate_conn
    conn.connect()
  File "/home/sherhin/projects/elate_bot/env/lib/python3.6/site-packages/telegram/vendor/ptb_urllib3/urllib3/connection.py", line 284, in connect
    conn = self._new_conn()
  File "/home/sherhin/projects/elate_bot/env/lib/python3.6/site-packages/telegram/vendor/ptb_urllib3/urllib3/contrib/socks.py", line 120, in _new_conn
    self, "Failed to establish a new connection: %s" % e)
telegram.vendor.ptb_urllib3.urllib3.exceptions.NewConnectionError: <telegram.vendor.ptb_urllib3.urllib3.contrib.socks.SOCKSHTTPSConnection object at 0x7f88dc1029b0>: Failed to establish a new connection: [Errno -2] Name or service not known

During handling of the above exception, another exception occurred:

Traceback (most recent call last):
  File "/home/sherhin/projects/elate_bot/env/lib/python3.6/site-packages/telegram/utils/request.py", line 203, in _request_wrapper
    resp = self._con_pool.request(*args, **kwargs)
  File "/home/sherhin/projects/elate_bot/env/lib/python3.6/site-packages/telegram/vendor/ptb_urllib3/urllib3/request.py", line 70, in request
    **urlopen_kw)
  File "/home/sherhin/projects/elate_bot/env/lib/python3.6/site-packages/telegram/vendor/ptb_urllib3/urllib3/request.py", line 148, in request_encode_body
    return self.urlopen(method, url, **extra_kw)
  File "/home/sherhin/projects/elate_bot/env/lib/python3.6/site-packages/telegram/vendor/ptb_urllib3/urllib3/poolmanager.py", line 244, in urlopen
    response = conn.urlopen(method, u.request_uri, **kw)
  File "/home/sherhin/projects/elate_bot/env/lib/python3.6/site-packages/telegram/vendor/ptb_urllib3/urllib3/connectionpool.py", line 695, in urlopen
    **response_kw)
  File "/home/sherhin/projects/elate_bot/env/lib/python3.6/site-packages/telegram/vendor/ptb_urllib3/urllib3/connectionpool.py", line 695, in urlopen
    **response_kw)
  File "/home/sherhin/projects/elate_bot/env/lib/python3.6/site-packages/telegram/vendor/ptb_urllib3/urllib3/connectionpool.py", line 695, in urlopen
    **response_kw)
  File "/home/sherhin/projects/elate_bot/env/lib/python3.6/site-packages/telegram/vendor/ptb_urllib3/urllib3/connectionpool.py", line 666, in urlopen
    _stacktrace=sys.exc_info()[2])
  File "/home/sherhin/projects/elate_bot/env/lib/python3.6/site-packages/telegram/vendor/ptb_urllib3/urllib3/util/retry.py", line 376, in increment
    raise MaxRetryError(_pool, url, error or ResponseError(cause))
telegram.vendor.ptb_urllib3.urllib3.exceptions.MaxRetryError: SOCKSHTTPSConnectionPool(host='api.telegram.org', port=443): Max retries exceeded with url: /bot804749789:AAGJPNOlbummUTJzQHPdhcNqy7JbVAT-f2Q/getUpdates (Caused by NewConnectionError('<telegram.vendor.ptb_urllib3.urllib3.contrib.socks.SOCKSHTTPSConnection object at 0x7f88dc1029b0>: Failed to establish a new connection: [Errno -2] Name or service not known',))

During handling of the above exception, another exception occurred:

Traceback (most recent call last):
  File "/home/sherhin/projects/elate_bot/env/lib/python3.6/site-packages/telegram/ext/updater.py", line 319, in _network_loop_retry
    if not action_cb():
  File "/home/sherhin/projects/elate_bot/env/lib/python3.6/site-packages/telegram/ext/updater.py", line 280, in polling_action_cb
    allowed_updates=allowed_updates)
  File "/home/sherhin/projects/elate_bot/env/lib/python3.6/site-packages/telegram/bot.py", line 65, in decorator
    result = func(self, *args, **kwargs)
  File "/home/sherhin/projects/elate_bot/env/lib/python3.6/site-packages/telegram/bot.py", line 1975, in get_updates
    result = self._request.post(url, data, timeout=float(read_latency) + float(timeout))
  File "/home/sherhin/projects/elate_bot/env/lib/python3.6/site-packages/telegram/utils/request.py", line 309, in post
    headers={'Content-Type': 'application/json'})
  File "/home/sherhin/projects/elate_bot/env/lib/python3.6/site-packages/telegram/utils/request.py", line 209, in _request_wrapper
    raise NetworkError('urllib3 HTTPError {0}'.format(error))
telegram.error.NetworkError: urllib3 HTTPError SOCKSHTTPSConnectionPool(host='api.telegram.org', port=443): Max retries exceeded with url: /bot804749789:AAGJPNOlbummUTJzQHPdhcNqy7JbVAT-f2Q/getUpdates (Caused by NewConnectionError('<telegram.vendor.ptb_urllib3.urllib3.contrib.socks.SOCKSHTTPSConnection object at 0x7f88dc1029b0>: Failed to establish a new connection: [Errno -2] Name or service not known',))
2019-06-17 16:16:27,929 - WARNING - Retrying (Retry(total=2, connect=None, read=None, redirect=None)) after connection broken by 'NewConnectionError('<telegram.vendor.ptb_urllib3.urllib3.contrib.socks.SOCKSHTTPSConnection object at 0x7f88dc1029e8>: Failed to establish a new connection: [Errno -2] Name or service not known',)': /bot804749789:AAGJPNOlbummUTJzQHPdhcNqy7JbVAT-f2Q/getUpdates
2019-06-17 16:16:27,931 - WARNING - Retrying (Retry(total=1, connect=None, read=None, redirect=None)) after connection broken by 'NewConnectionError('<telegram.vendor.ptb_urllib3.urllib3.contrib.socks.SOCKSHTTPSConnection object at 0x7f88df954e10>: Failed to establish a new connection: [Errno -2] Name or service not known',)': /bot804749789:AAGJPNOlbummUTJzQHPdhcNqy7JbVAT-f2Q/getUpdates
2019-06-17 16:16:27,933 - WARNING - Retrying (Retry(total=0, connect=None, read=None, redirect=None)) after connection broken by 'NewConnectionError('<telegram.vendor.ptb_urllib3.urllib3.contrib.socks.SOCKSHTTPSConnection object at 0x7f88dc1162e8>: Failed to establish a new connection: [Errno -2] Name or service not known',)': /bot804749789:AAGJPNOlbummUTJzQHPdhcNqy7JbVAT-f2Q/getUpdates
2019-06-17 16:16:27,936 - ERROR - Error while getting Updates: urllib3 HTTPError SOCKSHTTPSConnectionPool(host='api.telegram.org', port=443): Max retries exceeded with url: /bot804749789:AAGJPNOlbummUTJzQHPdhcNqy7JbVAT-f2Q/getUpdates (Caused by NewConnectionError('<telegram.vendor.ptb_urllib3.urllib3.contrib.socks.SOCKSHTTPSConnection object at 0x7f88dc1161d0>: Failed to establish a new connection: [Errno -2] Name or service not known',))
2019-06-17 16:16:27,937 - ERROR - No error handlers are registered, logging exception.
Traceback (most recent call last):
  File "/home/sherhin/projects/elate_bot/env/lib/python3.6/site-packages/telegram/vendor/ptb_urllib3/urllib3/contrib/socks.py", line 88, in _new_conn
    **extra_kw
  File "/home/sherhin/projects/elate_bot/env/lib/python3.6/site-packages/socks.py", line 180, in create_connection
    for r in socket.getaddrinfo(proxy_addr, proxy_port, 0, socket.SOCK_STREAM):
  File "/usr/lib/python3.6/socket.py", line 745, in getaddrinfo
    for res in _socket.getaddrinfo(host, port, family, type, proto, flags):
socket.gaierror: [Errno -2] Name or service not known

During handling of the above exception, another exception occurred:

Traceback (most recent call last):
  File "/home/sherhin/projects/elate_bot/env/lib/python3.6/site-packages/telegram/vendor/ptb_urllib3/urllib3/connectionpool.py", line 617, in urlopen
    chunked=chunked)
  File "/home/sherhin/projects/elate_bot/env/lib/python3.6/site-packages/telegram/vendor/ptb_urllib3/urllib3/connectionpool.py", line 360, in _make_request
    self._validate_conn(conn)
  File "/home/sherhin/projects/elate_bot/env/lib/python3.6/site-packages/telegram/vendor/ptb_urllib3/urllib3/connectionpool.py", line 857, in _validate_conn
    super(HTTPSConnectionPool, self)._validate_conn(conn)
  File "/home/sherhin/projects/elate_bot/env/lib/python3.6/site-packages/telegram/vendor/ptb_urllib3/urllib3/connectionpool.py", line 289, in _validate_conn
    conn.connect()
  File "/home/sherhin/projects/elate_bot/env/lib/python3.6/site-packages/telegram/vendor/ptb_urllib3/urllib3/connection.py", line 284, in connect
    conn = self._new_conn()
  File "/home/sherhin/projects/elate_bot/env/lib/python3.6/site-packages/telegram/vendor/ptb_urllib3/urllib3/contrib/socks.py", line 120, in _new_conn
    self, "Failed to establish a new connection: %s" % e)
telegram.vendor.ptb_urllib3.urllib3.exceptions.NewConnectionError: <telegram.vendor.ptb_urllib3.urllib3.contrib.socks.SOCKSHTTPSConnection object at 0x7f88dc1161d0>: Failed to establish a new connection: [Errno -2] Name or service not known

During handling of the above exception, another exception occurred:

Traceback (most recent call last):
  File "/home/sherhin/projects/elate_bot/env/lib/python3.6/site-packages/telegram/utils/request.py", line 203, in _request_wrapper
    resp = self._con_pool.request(*args, **kwargs)
  File "/home/sherhin/projects/elate_bot/env/lib/python3.6/site-packages/telegram/vendor/ptb_urllib3/urllib3/request.py", line 70, in request
    **urlopen_kw)
  File "/home/sherhin/projects/elate_bot/env/lib/python3.6/site-packages/telegram/vendor/ptb_urllib3/urllib3/request.py", line 148, in request_encode_body
    return self.urlopen(method, url, **extra_kw)
  File "/home/sherhin/projects/elate_bot/env/lib/python3.6/site-packages/telegram/vendor/ptb_urllib3/urllib3/poolmanager.py", line 244, in urlopen
    response = conn.urlopen(method, u.request_uri, **kw)
  File "/home/sherhin/projects/elate_bot/env/lib/python3.6/site-packages/telegram/vendor/ptb_urllib3/urllib3/connectionpool.py", line 695, in urlopen
    **response_kw)
  File "/home/sherhin/projects/elate_bot/env/lib/python3.6/site-packages/telegram/vendor/ptb_urllib3/urllib3/connectionpool.py", line 695, in urlopen
    **response_kw)
  File "/home/sherhin/projects/elate_bot/env/lib/python3.6/site-packages/telegram/vendor/ptb_urllib3/urllib3/connectionpool.py", line 695, in urlopen
    **response_kw)
  File "/home/sherhin/projects/elate_bot/env/lib/python3.6/site-packages/telegram/vendor/ptb_urllib3/urllib3/connectionpool.py", line 666, in urlopen
    _stacktrace=sys.exc_info()[2])
  File "/home/sherhin/projects/elate_bot/env/lib/python3.6/site-packages/telegram/vendor/ptb_urllib3/urllib3/util/retry.py", line 376, in increment
    raise MaxRetryError(_pool, url, error or ResponseError(cause))
telegram.vendor.ptb_urllib3.urllib3.exceptions.MaxRetryError: SOCKSHTTPSConnectionPool(host='api.telegram.org', port=443): Max retries exceeded with url: /bot804749789:AAGJPNOlbummUTJzQHPdhcNqy7JbVAT-f2Q/getUpdates (Caused by NewConnectionError('<telegram.vendor.ptb_urllib3.urllib3.contrib.socks.SOCKSHTTPSConnection object at 0x7f88dc1161d0>: Failed to establish a new connection: [Errno -2] Name or service not known',))

During handling of the above exception, another exception occurred:

Traceback (most recent call last):
  File "/home/sherhin/projects/elate_bot/env/lib/python3.6/site-packages/telegram/ext/updater.py", line 319, in _network_loop_retry
    if not action_cb():
  File "/home/sherhin/projects/elate_bot/env/lib/python3.6/site-packages/telegram/ext/updater.py", line 280, in polling_action_cb
    allowed_updates=allowed_updates)
  File "/home/sherhin/projects/elate_bot/env/lib/python3.6/site-packages/telegram/bot.py", line 65, in decorator
    result = func(self, *args, **kwargs)
  File "/home/sherhin/projects/elate_bot/env/lib/python3.6/site-packages/telegram/bot.py", line 1975, in get_updates
    result = self._request.post(url, data, timeout=float(read_latency) + float(timeout))
  File "/home/sherhin/projects/elate_bot/env/lib/python3.6/site-packages/telegram/utils/request.py", line 309, in post
    headers={'Content-Type': 'application/json'})
  File "/home/sherhin/projects/elate_bot/env/lib/python3.6/site-packages/telegram/utils/request.py", line 209, in _request_wrapper
    raise NetworkError('urllib3 HTTPError {0}'.format(error))
telegram.error.NetworkError: urllib3 HTTPError SOCKSHTTPSConnectionPool(host='api.telegram.org', port=443): Max retries exceeded with url: /bot804749789:AAGJPNOlbummUTJzQHPdhcNqy7JbVAT-f2Q/getUpdates (Caused by NewConnectionError('<telegram.vendor.ptb_urllib3.urllib3.contrib.socks.SOCKSHTTPSConnection object at 0x7f88dc1161d0>: Failed to establish a new connection: [Errno -2] Name or service not known',))
2019-06-18 19:46:26,264 - WARNING - Retrying (Retry(total=2, connect=None, read=None, redirect=None)) after connection broken by 'NewConnectionError('<telegram.vendor.ptb_urllib3.urllib3.contrib.socks.SOCKSHTTPSConnection object at 0x7f88dc1162b0>: Failed to establish a new connection: [Errno -2] Name or service not known',)': /bot804749789:AAGJPNOlbummUTJzQHPdhcNqy7JbVAT-f2Q/getUpdates
2019-06-18 19:46:26,266 - WARNING - Retrying (Retry(total=1, connect=None, read=None, redirect=None)) after connection broken by 'NewConnectionError('<telegram.vendor.ptb_urllib3.urllib3.contrib.socks.SOCKSHTTPSConnection object at 0x7f88dc1164e0>: Failed to establish a new connection: [Errno -2] Name or service not known',)': /bot804749789:AAGJPNOlbummUTJzQHPdhcNqy7JbVAT-f2Q/getUpdates
2019-06-18 19:46:26,269 - WARNING - Retrying (Retry(total=0, connect=None, read=None, redirect=None)) after connection broken by 'NewConnectionError('<telegram.vendor.ptb_urllib3.urllib3.contrib.socks.SOCKSHTTPSConnection object at 0x7f88dc116588>: Failed to establish a new connection: [Errno -2] Name or service not known',)': /bot804749789:AAGJPNOlbummUTJzQHPdhcNqy7JbVAT-f2Q/getUpdates
2019-06-18 19:46:26,271 - ERROR - Error while getting Updates: urllib3 HTTPError SOCKSHTTPSConnectionPool(host='api.telegram.org', port=443): Max retries exceeded with url: /bot804749789:AAGJPNOlbummUTJzQHPdhcNqy7JbVAT-f2Q/getUpdates (Caused by NewConnectionError('<telegram.vendor.ptb_urllib3.urllib3.contrib.socks.SOCKSHTTPSConnection object at 0x7f88dc116668>: Failed to establish a new connection: [Errno -2] Name or service not known',))
2019-06-18 19:46:26,271 - ERROR - No error handlers are registered, logging exception.
Traceback (most recent call last):
  File "/home/sherhin/projects/elate_bot/env/lib/python3.6/site-packages/telegram/vendor/ptb_urllib3/urllib3/contrib/socks.py", line 88, in _new_conn
    **extra_kw
  File "/home/sherhin/projects/elate_bot/env/lib/python3.6/site-packages/socks.py", line 180, in create_connection
    for r in socket.getaddrinfo(proxy_addr, proxy_port, 0, socket.SOCK_STREAM):
  File "/usr/lib/python3.6/socket.py", line 745, in getaddrinfo
    for res in _socket.getaddrinfo(host, port, family, type, proto, flags):
socket.gaierror: [Errno -2] Name or service not known

During handling of the above exception, another exception occurred:

Traceback (most recent call last):
  File "/home/sherhin/projects/elate_bot/env/lib/python3.6/site-packages/telegram/vendor/ptb_urllib3/urllib3/connectionpool.py", line 617, in urlopen
    chunked=chunked)
  File "/home/sherhin/projects/elate_bot/env/lib/python3.6/site-packages/telegram/vendor/ptb_urllib3/urllib3/connectionpool.py", line 360, in _make_request
    self._validate_conn(conn)
  File "/home/sherhin/projects/elate_bot/env/lib/python3.6/site-packages/telegram/vendor/ptb_urllib3/urllib3/connectionpool.py", line 857, in _validate_conn
    super(HTTPSConnectionPool, self)._validate_conn(conn)
  File "/home/sherhin/projects/elate_bot/env/lib/python3.6/site-packages/telegram/vendor/ptb_urllib3/urllib3/connectionpool.py", line 289, in _validate_conn
    conn.connect()
  File "/home/sherhin/projects/elate_bot/env/lib/python3.6/site-packages/telegram/vendor/ptb_urllib3/urllib3/connection.py", line 284, in connect
    conn = self._new_conn()
  File "/home/sherhin/projects/elate_bot/env/lib/python3.6/site-packages/telegram/vendor/ptb_urllib3/urllib3/contrib/socks.py", line 120, in _new_conn
    self, "Failed to establish a new connection: %s" % e)
telegram.vendor.ptb_urllib3.urllib3.exceptions.NewConnectionError: <telegram.vendor.ptb_urllib3.urllib3.contrib.socks.SOCKSHTTPSConnection object at 0x7f88dc116668>: Failed to establish a new connection: [Errno -2] Name or service not known

During handling of the above exception, another exception occurred:

Traceback (most recent call last):
  File "/home/sherhin/projects/elate_bot/env/lib/python3.6/site-packages/telegram/utils/request.py", line 203, in _request_wrapper
    resp = self._con_pool.request(*args, **kwargs)
  File "/home/sherhin/projects/elate_bot/env/lib/python3.6/site-packages/telegram/vendor/ptb_urllib3/urllib3/request.py", line 70, in request
    **urlopen_kw)
  File "/home/sherhin/projects/elate_bot/env/lib/python3.6/site-packages/telegram/vendor/ptb_urllib3/urllib3/request.py", line 148, in request_encode_body
    return self.urlopen(method, url, **extra_kw)
  File "/home/sherhin/projects/elate_bot/env/lib/python3.6/site-packages/telegram/vendor/ptb_urllib3/urllib3/poolmanager.py", line 244, in urlopen
    response = conn.urlopen(method, u.request_uri, **kw)
  File "/home/sherhin/projects/elate_bot/env/lib/python3.6/site-packages/telegram/vendor/ptb_urllib3/urllib3/connectionpool.py", line 695, in urlopen
    **response_kw)
  File "/home/sherhin/projects/elate_bot/env/lib/python3.6/site-packages/telegram/vendor/ptb_urllib3/urllib3/connectionpool.py", line 695, in urlopen
    **response_kw)
  File "/home/sherhin/projects/elate_bot/env/lib/python3.6/site-packages/telegram/vendor/ptb_urllib3/urllib3/connectionpool.py", line 695, in urlopen
    **response_kw)
  File "/home/sherhin/projects/elate_bot/env/lib/python3.6/site-packages/telegram/vendor/ptb_urllib3/urllib3/connectionpool.py", line 666, in urlopen
    _stacktrace=sys.exc_info()[2])
  File "/home/sherhin/projects/elate_bot/env/lib/python3.6/site-packages/telegram/vendor/ptb_urllib3/urllib3/util/retry.py", line 376, in increment
    raise MaxRetryError(_pool, url, error or ResponseError(cause))
telegram.vendor.ptb_urllib3.urllib3.exceptions.MaxRetryError: SOCKSHTTPSConnectionPool(host='api.telegram.org', port=443): Max retries exceeded with url: /bot804749789:AAGJPNOlbummUTJzQHPdhcNqy7JbVAT-f2Q/getUpdates (Caused by NewConnectionError('<telegram.vendor.ptb_urllib3.urllib3.contrib.socks.SOCKSHTTPSConnection object at 0x7f88dc116668>: Failed to establish a new connection: [Errno -2] Name or service not known',))

During handling of the above exception, another exception occurred:

Traceback (most recent call last):
  File "/home/sherhin/projects/elate_bot/env/lib/python3.6/site-packages/telegram/ext/updater.py", line 319, in _network_loop_retry
    if not action_cb():
  File "/home/sherhin/projects/elate_bot/env/lib/python3.6/site-packages/telegram/ext/updater.py", line 280, in polling_action_cb
    allowed_updates=allowed_updates)
  File "/home/sherhin/projects/elate_bot/env/lib/python3.6/site-packages/telegram/bot.py", line 65, in decorator
    result = func(self, *args, **kwargs)
  File "/home/sherhin/projects/elate_bot/env/lib/python3.6/site-packages/telegram/bot.py", line 1975, in get_updates
    result = self._request.post(url, data, timeout=float(read_latency) + float(timeout))
  File "/home/sherhin/projects/elate_bot/env/lib/python3.6/site-packages/telegram/utils/request.py", line 309, in post
    headers={'Content-Type': 'application/json'})
  File "/home/sherhin/projects/elate_bot/env/lib/python3.6/site-packages/telegram/utils/request.py", line 209, in _request_wrapper
    raise NetworkError('urllib3 HTTPError {0}'.format(error))
telegram.error.NetworkError: urllib3 HTTPError SOCKSHTTPSConnectionPool(host='api.telegram.org', port=443): Max retries exceeded with url: /bot804749789:AAGJPNOlbummUTJzQHPdhcNqy7JbVAT-f2Q/getUpdates (Caused by NewConnectionError('<telegram.vendor.ptb_urllib3.urllib3.contrib.socks.SOCKSHTTPSConnection object at 0x7f88dc116668>: Failed to establish a new connection: [Errno -2] Name or service not known',))
2019-06-18 19:46:37,676 - WARNING - Retrying (Retry(total=2, connect=None, read=None, redirect=None)) after connection broken by 'NewConnectionError('<telegram.vendor.ptb_urllib3.urllib3.contrib.socks.SOCKSHTTPSConnection object at 0x7f88dc116470>: Failed to establish a new connection: [Errno -2] Name or service not known',)': /bot804749789:AAGJPNOlbummUTJzQHPdhcNqy7JbVAT-f2Q/getUpdates
2019-06-18 19:46:37,910 - WARNING - Retrying (Retry(total=1, connect=None, read=None, redirect=None)) after connection broken by 'NewConnectionError('<telegram.vendor.ptb_urllib3.urllib3.contrib.socks.SOCKSHTTPSConnection object at 0x7f88df954e10>: Failed to establish a new connection: [Errno -2] Name or service not known',)': /bot804749789:AAGJPNOlbummUTJzQHPdhcNqy7JbVAT-f2Q/getUpdates
2019-06-18 19:46:37,912 - WARNING - Retrying (Retry(total=0, connect=None, read=None, redirect=None)) after connection broken by 'NewConnectionError('<telegram.vendor.ptb_urllib3.urllib3.contrib.socks.SOCKSHTTPSConnection object at 0x7f88dc102240>: Failed to establish a new connection: [Errno -2] Name or service not known',)': /bot804749789:AAGJPNOlbummUTJzQHPdhcNqy7JbVAT-f2Q/getUpdates
2019-06-18 19:46:37,914 - ERROR - Error while getting Updates: urllib3 HTTPError SOCKSHTTPSConnectionPool(host='api.telegram.org', port=443): Max retries exceeded with url: /bot804749789:AAGJPNOlbummUTJzQHPdhcNqy7JbVAT-f2Q/getUpdates (Caused by NewConnectionError('<telegram.vendor.ptb_urllib3.urllib3.contrib.socks.SOCKSHTTPSConnection object at 0x7f88dc102358>: Failed to establish a new connection: [Errno -2] Name or service not known',))
2019-06-18 19:46:37,914 - ERROR - No error handlers are registered, logging exception.
Traceback (most recent call last):
  File "/home/sherhin/projects/elate_bot/env/lib/python3.6/site-packages/telegram/vendor/ptb_urllib3/urllib3/contrib/socks.py", line 88, in _new_conn
    **extra_kw
  File "/home/sherhin/projects/elate_bot/env/lib/python3.6/site-packages/socks.py", line 180, in create_connection
    for r in socket.getaddrinfo(proxy_addr, proxy_port, 0, socket.SOCK_STREAM):
  File "/usr/lib/python3.6/socket.py", line 745, in getaddrinfo
    for res in _socket.getaddrinfo(host, port, family, type, proto, flags):
socket.gaierror: [Errno -2] Name or service not known

During handling of the above exception, another exception occurred:

Traceback (most recent call last):
  File "/home/sherhin/projects/elate_bot/env/lib/python3.6/site-packages/telegram/vendor/ptb_urllib3/urllib3/connectionpool.py", line 617, in urlopen
    chunked=chunked)
  File "/home/sherhin/projects/elate_bot/env/lib/python3.6/site-packages/telegram/vendor/ptb_urllib3/urllib3/connectionpool.py", line 360, in _make_request
    self._validate_conn(conn)
  File "/home/sherhin/projects/elate_bot/env/lib/python3.6/site-packages/telegram/vendor/ptb_urllib3/urllib3/connectionpool.py", line 857, in _validate_conn
    super(HTTPSConnectionPool, self)._validate_conn(conn)
  File "/home/sherhin/projects/elate_bot/env/lib/python3.6/site-packages/telegram/vendor/ptb_urllib3/urllib3/connectionpool.py", line 289, in _validate_conn
    conn.connect()
  File "/home/sherhin/projects/elate_bot/env/lib/python3.6/site-packages/telegram/vendor/ptb_urllib3/urllib3/connection.py", line 284, in connect
    conn = self._new_conn()
  File "/home/sherhin/projects/elate_bot/env/lib/python3.6/site-packages/telegram/vendor/ptb_urllib3/urllib3/contrib/socks.py", line 120, in _new_conn
    self, "Failed to establish a new connection: %s" % e)
telegram.vendor.ptb_urllib3.urllib3.exceptions.NewConnectionError: <telegram.vendor.ptb_urllib3.urllib3.contrib.socks.SOCKSHTTPSConnection object at 0x7f88dc102358>: Failed to establish a new connection: [Errno -2] Name or service not known

During handling of the above exception, another exception occurred:

Traceback (most recent call last):
  File "/home/sherhin/projects/elate_bot/env/lib/python3.6/site-packages/telegram/utils/request.py", line 203, in _request_wrapper
    resp = self._con_pool.request(*args, **kwargs)
  File "/home/sherhin/projects/elate_bot/env/lib/python3.6/site-packages/telegram/vendor/ptb_urllib3/urllib3/request.py", line 70, in request
    **urlopen_kw)
  File "/home/sherhin/projects/elate_bot/env/lib/python3.6/site-packages/telegram/vendor/ptb_urllib3/urllib3/request.py", line 148, in request_encode_body
    return self.urlopen(method, url, **extra_kw)
  File "/home/sherhin/projects/elate_bot/env/lib/python3.6/site-packages/telegram/vendor/ptb_urllib3/urllib3/poolmanager.py", line 244, in urlopen
    response = conn.urlopen(method, u.request_uri, **kw)
  File "/home/sherhin/projects/elate_bot/env/lib/python3.6/site-packages/telegram/vendor/ptb_urllib3/urllib3/connectionpool.py", line 695, in urlopen
    **response_kw)
  File "/home/sherhin/projects/elate_bot/env/lib/python3.6/site-packages/telegram/vendor/ptb_urllib3/urllib3/connectionpool.py", line 695, in urlopen
    **response_kw)
  File "/home/sherhin/projects/elate_bot/env/lib/python3.6/site-packages/telegram/vendor/ptb_urllib3/urllib3/connectionpool.py", line 695, in urlopen
    **response_kw)
  File "/home/sherhin/projects/elate_bot/env/lib/python3.6/site-packages/telegram/vendor/ptb_urllib3/urllib3/connectionpool.py", line 666, in urlopen
    _stacktrace=sys.exc_info()[2])
  File "/home/sherhin/projects/elate_bot/env/lib/python3.6/site-packages/telegram/vendor/ptb_urllib3/urllib3/util/retry.py", line 376, in increment
    raise MaxRetryError(_pool, url, error or ResponseError(cause))
telegram.vendor.ptb_urllib3.urllib3.exceptions.MaxRetryError: SOCKSHTTPSConnectionPool(host='api.telegram.org', port=443): Max retries exceeded with url: /bot804749789:AAGJPNOlbummUTJzQHPdhcNqy7JbVAT-f2Q/getUpdates (Caused by NewConnectionError('<telegram.vendor.ptb_urllib3.urllib3.contrib.socks.SOCKSHTTPSConnection object at 0x7f88dc102358>: Failed to establish a new connection: [Errno -2] Name or service not known',))

During handling of the above exception, another exception occurred:

Traceback (most recent call last):
  File "/home/sherhin/projects/elate_bot/env/lib/python3.6/site-packages/telegram/ext/updater.py", line 319, in _network_loop_retry
    if not action_cb():
  File "/home/sherhin/projects/elate_bot/env/lib/python3.6/site-packages/telegram/ext/updater.py", line 280, in polling_action_cb
    allowed_updates=allowed_updates)
  File "/home/sherhin/projects/elate_bot/env/lib/python3.6/site-packages/telegram/bot.py", line 65, in decorator
    result = func(self, *args, **kwargs)
  File "/home/sherhin/projects/elate_bot/env/lib/python3.6/site-packages/telegram/bot.py", line 1975, in get_updates
    result = self._request.post(url, data, timeout=float(read_latency) + float(timeout))
  File "/home/sherhin/projects/elate_bot/env/lib/python3.6/site-packages/telegram/utils/request.py", line 309, in post
    headers={'Content-Type': 'application/json'})
  File "/home/sherhin/projects/elate_bot/env/lib/python3.6/site-packages/telegram/utils/request.py", line 209, in _request_wrapper
    raise NetworkError('urllib3 HTTPError {0}'.format(error))
telegram.error.NetworkError: urllib3 HTTPError SOCKSHTTPSConnectionPool(host='api.telegram.org', port=443): Max retries exceeded with url: /bot804749789:AAGJPNOlbummUTJzQHPdhcNqy7JbVAT-f2Q/getUpdates (Caused by NewConnectionError('<telegram.vendor.ptb_urllib3.urllib3.contrib.socks.SOCKSHTTPSConnection object at 0x7f88dc102358>: Failed to establish a new connection: [Errno -2] Name or service not known',))
2019-06-18 19:52:38,930 - INFO - Received signal 2 (SIGINT), stopping...
2019-06-18 19:52:39,059 - WARNING - Exiting immediately!
2019-06-18 19:56:10,229 - INFO - Received signal 2 (SIGINT), stopping...
2019-06-18 19:56:10,551 - WARNING - Exiting immediately!
